Workbook

Sheet WYNIKI
B1: MSE | C1: MAE
A2: naiwna | B2: =naiwna!GV2 -> 2.7309625 | C2: =naiwna!GV3 -> 1.3181929 | E2: =B2/$B$2 -> 1 | F2: =C2/$C$2 -> 1
A3: reg_lin | B3: =reg_lin!GV2 -> 1.0091794 | C3: =reg_lin!GV3 -> 0.80169721 | E3: =B3/$B$2 -> 0.3695325 | F3: =C3/$C$2 -> 0.60817896
A4: SVR_lin | B4: =SVR_lin!GV2 -> 0.98525062 | C4: =SVR_lin!GV3 -> 0.79052755 | E4: =B4/$B$2 -> 0.36077046 | F4: =C4/$C$2 -> 0.5997055
A5: SVR_rbf | B5: =SVR_rbf!GV2 -> 1.0069866 | C5: =SVR_rbf!GV3 -> 0.79871736 | E5: =B5/$B$2 -> 0.36872954 | F5: =C5/$C$2 -> 0.6059184
A6: RF | B6: =RF!GV2 -> 1.0194153 | C6: =RF!GV3 -> 0.80544434 | E6: =B6/$B$2 -> 0.3732806 | F6: =C6/$C$2 -> 0.61102158
A7: LGBM | B7: =LGBM!GV2 -> 1.0313339 | C7: =LGBM!GV3 -> 0.81043115 | E7: =B7/$B$2 -> 0.37764485 | F7: =C7/$C$2 -> 0.61480465
A8: MLP | B8: =MLP!GV2 -> 1.0300036 | C8: =MLP!GV3 -> 0.81015244 | E8: =B8 /$B$2 -> 0.37715772 | F8: =C8 /$C$2 -> 0.61459322
A9: NBEATS | B9: =NBEATS!GV2 -> 2.1519241 | C9: =NBEATS!GV3 -> 1.1499838 | E9: =B9 /$B$2 -> 0.78797275 | F9: =C9 /$C$2 -> 0.87239417
A10: NBEATS_nblocks | B10: =NBEATS_nblocks!GV2 -> 2.0324488 | C10: =NBEATS_nblocks!GV3 -> 1.0783749 | E10: =B10 /$B$2 -> 0.74422435 | F10: =C10 /$C$2 -> 0.81807063
A11: GRU | B11: =GRU!GV2 -> 1.6805793 | C11: =GRU!GV3 -> 1.0226261 | E11: =B11 /$B$2 -> 0.61537985 | F11: =C11 /$C$2 -> 0.77577879
A12: RMOK | B12: =RMOK!GV2 -> 1.1745281 | C12: =RMOK!GV3 -> 0.86251225 | E12: =B12 /$B$2 -> 0.43007843 | F12: =C12 /$C$2 -> 0.65431411
A13: TCN | B13: =TCN!GV2 -> 1.2384455 | C13: =TCN!GV3 -> 0.88851667 | E13: =B13 /$B$2 -> 0.45348316 | F13: =C13 /$C$2 -> 0.67404144
A14: TFT | B14: =TFT!GV2 -> 1.1059307 | C14: =TFT!GV3 -> 0.83733759 | E14: =B14 /$B$2 -> 0.40496004 | F14: =C14 /$C$2 -> 0.63521626

Sheet naiwna
A1: prawdziwe | CX1: błędy | GX1: moduły błędów
A2: 1.0045752 | B2: 0.86045762 | C2: 1.8698138 | D2: -2.1050089 | E2: 1.4475623 | F2: -1.0252553 | G2: 0.67223197 | H2: -0.12593962 | I2: 0.66403577 | J2: 0.48728257 | K2: 1.290437 | L2: -0.10407828 | M2: -1.3697692 | N2: -0.94641923 | O2: -0.0023437728 | P2: 1.3802507 | Q2: -1.0370113 | R2: -0.030391357 | S2: 0.74253305 | T2: -0.53145641 | U2: -1.1101401 | V2: -0.82296607 | W2: 1.0494791 | X2: -0.65331935 | Y2: 1.7979421 | Z2: 1.3992228 | AA2: -1.5339369 | AB2: -0.042305234 | AC2: 0.12857575 | AD2: -0.013076373 | AE2: 1.2471412 | AF2: -0.67416157 | AG2: -1.0774626 | AH2: -0.23065657 | AI2: 0.098923911 | AJ2: -0.10926624 | AK2: 0.40753701 | AL2: 0.25099561 | AM2: 0.1810706 | AN2: 0.51702964 | AO2: 0.10157248 | AP2: 1.7962585 | AQ2: -2.0613279 | AR2: -1.1304584 | AS2: -0.066769994 | AT2: 0.71444283 | AU2: -1.1715007 | AV2: -1.2605332 | AW2: -0.23999569 | AX2: 0.42370321 | AY2: 0.2509917 | AZ2: 1.2083722 | BA2: -0.61256059 | BB2: 1.7598784 | BC2: -0.96783713 | BD2: 0.81826571 | BE2: -0.30807434 | BF2: -0.33039331 | BG2: -0.23850679 | BH2: 0.63716688 | BI2: 1.7706939 | BJ2: 0.095477389 | BK2: 1.1379093 | BL2: -0.84198992 | BM2: 0.013368058 | BN2: 0.78749319 | BO2: -0.63159279 | BP2: -1.2322297 | BQ2: 0.79350603 | BR2: 0.34769499 | BS2: -0.96262952 | BT2: 1.1503698 | BU2: -1.03384 | BV2: -0.42687992 | BW2: 0.31755047 | BX2: -0.48356092 | BY2: 1.8675054 | BZ2: -0.66249515 | CA2: -0.35457305 | CB2: -0.30536157 | CC2: -0.95470905 | CD2: -0.42355842 | CE2: 0.47222179 | CF2: -0.64173278 | CG2: 1.3009344 | CH2: 0.2840916 | CI2: -0.44328147 | CJ2: -0.19857469 | CK2: -1.2178243 | CL2: -1.4850007 | CM2: -0.57576538 | CN2: 0.14583535 | CO2: 0.67415011 | CP2: 0.32959936 | CQ2: 0.58478148 | CR2: -1.2458844 | CS2: -0.884995 | CT2: -0.47582754 | CU2: -0.96097865 | CV2: 0.12841158 | CX2: =A2-A58 -> 1.5785484 | CY2: =B2-B58 -> 1.6624556 | CZ2: =C2-C58 -> 2.5131969 | DA2: =D2-D58 -> -1.6488889 | DB2: =E2-E58 -> 2.0979357 | DC2: =F2-F58 -> 0.97316408 | DD2: =G2-G58 -> 1.5529391 | DE2: =H2-H58 -> -0.6147307 | ... GS2: =CV2-CV58 -> 0.16558639 | GU2: MSE= | GV2: =SUMSQ(CX2:GS51)/5000 -> 2.7309625 | GX2: =ABS(CX2) -> 1.5785484 | GY2: =ABS(CY2) -> 1.6624556 | GZ2: =ABS(CZ2) -> 2.5131969 | HA2: =ABS(DA2) -> 1.6488889 | HB2: =ABS(DB2) -> 2.0979357 | HC2: =ABS(DC2) -> 0.97316408 | HD2: =ABS(DD2) -> 1.5529391 | HE2: =ABS(DE2) -> 0.6147307 | ... KS2: =ABS(GS2) -> 0.16558639
A3: -0.18009008 | B3: -1.3995218 | C3: -1.1065712 | D3: 0.26515134 | E3: -1.5106233 | F3: -0.72579301 | G3: -0.018941789 | H3: -1.364184 | I3: -0.75414951 | J3: 1.1530312 | K3: -0.28910409 | L3: -1.0377032 | M3: 0.35276624 | N3: -0.057459491 | O3: -0.59752539 | P3: -0.54406168 | Q3: -1.3134701 | R3: -1.1236538 | S3: -2.4756209 | T3: -0.93547221 | U3: 0.63002714 | V3: 0.214281 | W3: -0.12213064 | X3: 0.89266895 | Y3: 0.77325208 | Z3: 0.95860215 | AA3: 0.40676258 | AB3: 0.57405627 | AC3: -0.43296252 | AD3: -0.015507445 | AE3: -0.5218363 | AF3: -0.12545251 | AG3: 2.3498354 | AH3: -0.57252497 | AI3: 0.38995911 | AJ3: 0.3497336 | AK3: 1.1452455 | AL3: -1.0909801 | AM3: -1.4844856 | AN3: -1.5964657 | AO3: 0.66834705 | AP3: -1.0871984 | AQ3: 0.75976587 | AR3: 0.99485273 | AS3: 0.7816544 | AT3: -0.090342353 | AU3: 0.10096442 | AV3: 0.58093495 | AW3: -0.025259463 | AX3: -2.5963848 | AY3: -1.2886212 | AZ3: -0.5677279 | BA3: 0.81243667 | BB3: -1.4035666 | BC3: 0.79856109 | BD3: 0.55501781 | BE3: 0.26768604 | BF3: 0.88084358 | BG3: 0.81702522 | BH3: -0.43372653 | BI3: 0.46191722 | BJ3: 0.67816475 | BK3: -0.91124764 | BL3: 0.086291002 | BM3: -0.10709826 | BN3: -0.41788476 | BO3: -0.083762191 | BP3: 0.39812825 | BQ3: 0.13633732 | BR3: -0.037644512 | BS3: 0.079897432 | BT3: 0.013915045 | BU3: -0.63482231 | BV3: 1.0884056 | BW3: -1.3043484 | BX3: 1.0869835 | BY3: -0.30253368 | BZ3: -0.31901241 | CA3: -0.38148891 | CB3: 1.0098949 | CC3: -0.16749578 | CD3: -0.29860421 | CE3: -0.42964982 | CF3: 0.19115581 | CG3: -0.55481318 | CH3: -1.251886 | CI3: -0.75024835 | CJ3: -0.07691277 | CK3: -0.7935302 | CL3: 0.8080841 | CM3: -0.65373048 | CN3: -0.57998171 | CO3: 0.58092369 | CP3: -0.26393276 | CQ3: -0.044161898 | CR3: -0.2454484 | CS3: 0.22118189 | CT3: -0.11840245 | CU3: -0.03947174 | CV3: 0.28381098 | CX3: =A3-A59 -> -1.1846653 | CY3: =B3-B59 -> -2.2599794 | CZ3: =C3-C59 -> -2.976385 | DA3: =D3-D59 -> 2.3701602 | DB3: =E3-E59 -> -2.9581856 | DC3: =F3-F59 -> 0.29946225 | DD3: =G3-G59 -> -0.69117376 | DE3: =H3-H59 -> -1.2382444 | ... GS3: =CV3-CV59 -> 0.1553994 | GU3: MAE= | GV3: =SUM(GX2:KS51)/5000 -> 1.3181929 | GX3: =ABS(CX3) -> 1.1846653 | GY3: =ABS(CY3) -> 2.2599794 | GZ3: =ABS(CZ3) -> 2.976385 | HA3: =ABS(DA3) -> 2.3701602 | HB3: =ABS(DB3) -> 2.9581856 | HC3: =ABS(DC3) -> 0.29946225 | HD3: =ABS(DD3) -> 0.69117376 | HE3: =ABS(DE3) -> 1.2382444 | ... KS3: =ABS(GS3) -> 0.1553994
A4: 0.71082607 | B4: 1.5167401 | C4: 0.41150468 | D4: 0.36998253 | E4: 0.62535905 | F4: -0.8097624 | G4: -0.17697263 | H4: 0.31614481 | I4: 0.36674015 | J4: 0.17305055 | K4: -0.090686332 | L4: -0.48695115 | M4: -1.247738 | N4: -0.27338663 | O4: 1.2454232 | P4: 0.11142743 | Q4: 0.49482118 | R4: 1.4813385 | S4: 1.6032843 | T4: -0.17371974 | U4: -2.1254313 | V4: -2.3153417 | W4: 1.6513201 | X4: 0.24696982 | Y4: -0.08393172 | Z4: 0.46859397 | AA4: 0.70769619 | AB4: 2.0432101 | AC4: -0.21116124 | AD4: 0.53688984 | AE4: 0.55807678 | AF4: -1.3361494 | AG4: 1.0850432 | AH4: -0.26463723 | AI4: -0.40264002 | AJ4: 0.19970444 | AK4: -0.42504337 | AL4: 0.83172876 | AM4: 3.1543696 | AN4: 1.0022817 | AO4: -0.12562547 | AP4: 0.079844435 | AQ4: -0.1598307 | AR4: -2.6055824 | AS4: -0.88682794 | AT4: -0.28543632 | AU4: -1.5501876 | AV4: -0.55660318 | AW4: -0.066673404 | AX4: 1.2051761 | AY4: -0.27698297 | AZ4: 0.71253322 | BA4: 1.2303401 | BB4: 0.5426154 | BC4: -0.60460652 | BD4: 0.7488549 | BE4: 0.096544966 | BF4: -1.0124995 | BG4: -1.9193298 | BH4: -0.7631593 | BI4: 0.13631066 | BJ4: -0.63526706 | BK4: -1.036477 | BL4: 0.98103377 | BM4: -0.11759196 | BN4: 0.76051477 | BO4: -0.912031 | BP4: -0.079118837 | BQ4: -0.88147065 | BR4: 0.29105508 | BS4: 0.56567904 | BT4: 0.28814457 | BU4: 1.8659941 | BV4: -0.78742117 | BW4: -0.059278462 | BX4: 0.30474776 | BY4: -0.33709964 | BZ4: -0.63478421 | CA4: 0.13766466 | CB4: 1.4648273 | CC4: 0.59950983 | CD4: 1.4652752 | CE4: -0.52407171 | CF4: 0.8540012 | CG4: 0.076054423 | CH4: 0.94267005 | CI4: -0.26441869 | CJ4: -1.3083529 | CK4: 0.86864066 | CL4: -0.49948247 | CM4: 0.34462273 | CN4: -0.41504815 | CO4: -1.6908682 | CP4: 0.45880238 | CQ4: -0.20508334 | CR4: -1.496307 | CS4: -0.81340969 | CT4: -0.64297391 | CU4: 0.36801566 | CV4: -0.35441646 | CX4: =A4-A60 -> 0.89091615 | CY4: =B4-B60 -> 2.9162619 | CZ4: =C4-C60 -> 1.5180759 | DA4: =D4-D60 -> 0.10483118 | DB4: =E4-E60 -> 2.1359824 | DC4: =F4-F60 -> -0.083969393 | DD4: =G4-G60 -> -0.15803085 | DE4: =H4-H60 -> 1.6803288 | ... GS4: =CV4-CV60 -> -0.63822744 | GX4: =ABS(CX4) -> 0.89091615 | GY4: =ABS(CY4) -> 2.9162619 | GZ4: =ABS(CZ4) -> 1.5180759 | HA4: =ABS(DA4) -> 0.10483118 | HB4: =ABS(DB4) -> 2.1359824 | HC4: =ABS(DC4) -> 0.083969393 | HD4: =ABS(DD4) -> 0.15803085 | HE4: =ABS(DE4) -> 1.6803288 | ... KS4: =ABS(GS4) -> 0.63822744
A5: 0.19528307 | B5: 0.070272179 | C5: 2.3307239 | D5: 0.16426452 | E5: -0.00826181 | F5: 1.070545 | G5: 0.18920009 | H5: -1.5271531 | I5: -0.73412803 | J5: 0.26823312 | K5: 0.75564968 | L5: -1.3158187 | M5: -0.2556062 | N5: 1.9705174 | O5: -0.0034363221 | P5: 1.0788113 | Q5: -0.64823831 | R5: -0.20582305 | S5: -0.31956953 | T5: 0.78591218 | U5: 0.76997034 | V5: -0.74746513 | W5: 0.64951353 | X5: 1.7429059 | Y5: -0.36705286 | Z5: -0.28687303 | AA5: -1.2082006 | AB5: -1.1688164 | AC5: 1.0715797 | AD5: -0.016501272 | AE5: -1.4064491 | AF5: -0.15752638 | AG5: -2.038595 | AH5: 1.4312543 | AI5: -0.31882525 | AJ5: -0.38572984 | AK5: 0.32059502 | AL5: 0.40031772 | AM5: -1.9999105 | AN5: -1.3939438 | AO5: 0.3516656 | AP5: -1.5916389 | AQ5: 0.089305989 | AR5: 2.4834563 | AS5: 0.0006296959 | AT5: 0.35865762 | AU5: 0.25826128 | AV5: 1.3480748 | AW5: 0.27141216 | AX5: -0.81618362 | AY5: 0.33077988 | AZ5: 0.32347161 | BA5: -0.90187787 | BB5: -1.0451719 | BC5: 1.8917953 | BD5: -0.28921511 | BE5: -0.094369938 | BF5: -0.43543668 | BG5: 1.5921536 | BH5: -0.42053 | BI5: 1.6057866 | BJ5: 0.22393454 | BK5: -0.44880594 | BL5: -0.50296639 | BM5: 0.45276202 | BN5: 0.34616565 | BO5: 2.1381212 | BP5: -1.2300404 | BQ5: -0.58178824 | BR5: -0.54441535 | BS5: -0.47215521 | BT5: -0.2142818 | BU5: -0.50842339 | BV5: -1.6475628 | BW5: -0.60946484 | BX5: -3.2377357 | BY5: 0.43019656 | BZ5: -0.53745005 | CA5: -0.25607344 | CB5: 0.53662066 | CC5: -0.30848259 | CD5: -0.84927229 | CE5: 2.1248562 | CF5: -1.5090064 | CG5: -0.67012608 | CH5: 0.22208709 | CI5: 0.25083498 | CJ5: -0.3060921 | CK5: -1.0098238 | CL5: 1.4735299 | CM5: 0.26854869 | CN5: 0.63459729 | CO5: 0.16405472 | CP5: -0.33550848 | CQ5: 0.91895777 | CR5: 0.026375271 | CS5: -0.16591591 | CT5: 1.548544 | CU5: 0.49965162 | CV5: 0.1684067 | CX5: =A5-A61 -> -0.515543 | CY5: =B5-B61 -> -1.4464679 | CZ5: =C5-C61 -> 1.9192192 | DA5: =D5-D61 -> -0.20571801 | DB5: =E5-E61 -> -0.63362086 | DC5: =F5-F61 -> 1.8803074 | DD5: =G5-G61 -> 0.36617272 | DE5: =H5-H61 -> -1.8432979 | ... GS5: =CV5-CV61 -> 0.52282316 | GX5: =ABS(CX5) -> 0.515543 | GY5: =ABS(CY5) -> 1.4464679 | GZ5: =ABS(CZ5) -> 1.9192192 | HA5: =ABS(DA5) -> 0.20571801 | HB5: =ABS(DB5) -> 0.63362086 | HC5: =ABS(DC5) -> 1.8803074 | HD5: =ABS(DD5) -> 0.36617272 | HE5: =ABS(DE5) -> 1.8432979 | ... KS5: =ABS(GS5) -> 0.52282316
A6: -2.4612794 | B6: -1.5197913 | C6: -0.9232051 | D6: 0.046528272 | E6: -1.7971789 | F6: -0.88425217 | G6: 0.048564968 | H6: 0.68364216 | I6: 1.276401 | J6: 0.11393298 | K6: -1.3684073 | L6: -0.3333304 | M6: -0.0027177427 | N6: -2.605137 | O6: -0.8114987 | P6: 1.2441256 | Q6: 2.6934714 | R6: -0.87692546 | S6: 1.4487416 | T6: -0.51282784 | U6: 0.35765476 | V6: 0.10040836 | W6: -0.20982712 | X6: 0.55133277 | Y6: -0.6116318 | Z6: 0.18137602 | AA6: -0.53971853 | AB6: -0.16059548 | AC6: -1.7242258 | AD6: 1.5464526 | AE6: 0.84153676 | AF6: 0.46981715 | AG6: -0.24397167 | AH6: -1.3709417 | AI6: 0.27615514 | AJ6: 1.080074 | AK6: 1.3470868 | AL6: 0.35617103 | AM6: 2.6108095 | AN6: 1.9073722 | AO6: -0.34889452 | AP6: 1.8920591 | AQ6: -0.8449728 | AR6: -0.96160739 | AS6: -0.1977551 | AT6: 0.37407495 | AU6: 1.961783 | AV6: -0.7724398 | AW6: 0.041004832 | AX6: -0.50868681 | AY6: -1.1818113 | AZ6: 0.7843156 | BA6: -0.092956538 | BB6: -0.52871725 | BC6: -2.1890646 | BD6: -0.40359123 | BE6: 1.4896729 | BF6: 1.4249842 | BG6: 0.87770063 | BH6: 0.1338212 | BI6: -1.7294733 | BJ6: 1.2184066 | BK6: -2.6748637 | BL6: -1.5393713 | BM6: 1.3250854 | BN6: 0.086045072 | BO6: -1.4149741 | BP6: 0.6622829 | BQ6: 0.5637236 | BR6: 0.36085204 | BS6: 0.97553836 | BT6: -0.22063659 | BU6: 0.60656085 | BV6: 1.2186695 | BW6: 0.71548715 | BX6: 0.99901988 | BY6: 1.2076183 | BZ6: 0.40554347 | CA6: -0.048722104 | CB6: -0.84080884 | CC6: 1.0723512 | CD6: 0.48040724 | CE6: 0.82215516 | CF6: -1.0202905 | CG6: 1.6991655 | CH6: 0.90521008 | CI6: 2.0506287 | CJ6: 0.26127303 | CK6: 0.18210548 | CL6: -2.0793195 | CM6: -0.51577072 | CN6: -0.36356009 | CO6: -0.14435069 | CP6: -0.36651702 | CQ6: -0.20062698 | CR6: -1.5597227 | CS6: -1.8182788 | CT6: 1.432203 | CU6: -0.12008105 | CV6: 0.13649134 | CX6: =A6-A62 -> -2.6565624 | CY6: =B6-B62 -> -1.5900635 | CZ6: =C6-C62 -> -3.253929 | DA6: =D6-D62 -> -0.11773624 | DB6: =E6-E62 -> -1.7889171 | DC6: =F6-F62 -> -1.9547972 | DD6: =G6-G62 -> -0.14063512 | DE6: =H6-H62 -> 2.2107952 | ... GS6: =CV6-CV62 -> -0.031915359 | GX6: =ABS(CX6) -> 2.6565624 | GY6: =ABS(CY6) -> 1.5900635 | GZ6: =ABS(CZ6) -> 3.253929 | HA6: =ABS(DA6) -> 0.11773624 | HB6: =ABS(DB6) -> 1.7889171 | HC6: =ABS(DC6) -> 1.9547972 | HD6: =ABS(DD6) -> 0.14063512 | HE6: =ABS(DE6) -> 2.2107952 | ... KS6: =ABS(GS6) -> 0.031915359
A7: 0.99876329 | B7: -0.23621245 | C7: 0.74844991 | D7: 0.089935082 | E7: 0.21258452 | F7: 0.081449636 | G7: 0.55195386 | H7: 0.17765911 | I7: 0.21196183 | J7: 0.69023481 | K7: 0.95854446 | L7: 0.067075377 | M7: -0.91470927 | N7: 1.9758905 | O7: 0.067970504 | P7: -0.89947174 | Q7: -1.845991 | R7: 2.8355884 | S7: 0.30548861 | T7: 0.19688069 | U7: -0.40070718 | V7: 0.79351584 | W7: 1.5263557 | X7: 1.0194282 | Y7: -0.85418421 | Z7: 1.3391908 | AA7: 0.089023229 | AB7: 1.6839888 | AC7: 0.34020434 | AD7: 0.015744254 | AE7: -2.2566002 | AF7: 0.31371316 | AG7: 0.33105235 | AH7: 1.6102512 | AI7: -1.9863925 | AJ7: -0.19466218 | AK7: -3.5528852 | AL7: 0.073884642 | AM7: -0.33263281 | AN7: 0.0066323675 | AO7: 0.68866049 | AP7: -1.0825839 | AQ7: -1.192504 | AR7: 1.1434955 | AS7: -0.61156965 | AT7: -2.808362 | AU7: 0.94795869 | AV7: 1.1389063 | AW7: 2.0461186 | AX7: 1.5158802 | AY7: 1.2142172 | AZ7: 0.41701593 | BA7: -0.23588643 | BB7: 0.47913557 | BC7: -0.58024954 | BD7: -0.50478564 | BE7: -1.6544835 | BF7: 0.43036118 | BG7: -1.4252423 | BH7: -0.32741765 | BI7: -0.32987765 | BJ7: -0.31940855 | BK7: 2.4726023 | BL7: -1.0184477 | BM7: -0.96246334 | BN7: 1.2875002 | BO7: 1.7118444 | BP7: 1.0788255 | BQ7: 0.42951425 | BR7: 1.8933326 | BS7: -2.0360029 | BT7: 1.2351396 | BU7: -0.5809311 | BV7: -1.0947542 | BW7: -0.2629218 | BX7: -0.96101842 | BY7: -1.4501027 | BZ7: -1.4230169 | CA7: -0.63657501 | CB7: 0.32171335 | CC7: -1.0806061 | CD7: 0.29450672 | CE7: -1.2457635 | CF7: 0.60001103 | CG7: -0.0085481799 | CH7: 0.83985729 | CI7: -0.75264571 | CJ7: -0.87105129 | CK7: -0.19430297 | CL7: 0.42584426 | CM7: 1.403043 | CN7: -0.34302033 | CO7: 0.8381983 | CP7: 1.5510578 | CQ7: -1.4304633 | CR7: -0.31186904 | CS7: 1.3323572 | CT7: -1.5807874 | CU7: -1.1821892 | CV7: -0.16201845 | CX7: =A7-A63 -> 3.4600427 | CY7: =B7-B63 -> 1.2835789 | CZ7: =C7-C63 -> 1.671655 | DA7: =D7-D63 -> 0.04340681 | DB7: =E7-E63 -> 2.0097635 | DC7: =F7-F63 -> 0.96570181 | DD7: =G7-G63 -> 0.5033889 | DE7: =H7-H63 -> -0.50598305 | ... GS7: =CV7-CV63 -> -0.29850979 | GX7: =ABS(CX7) -> 3.4600427 | GY7: =ABS(CY7) -> 1.2835789 | GZ7: =ABS(CZ7) -> 1.671655 | HA7: =ABS(DA7) -> 0.04340681 | HB7: =ABS(DB7) -> 2.0097635 | HC7: =ABS(DC7) -> 0.96570181 | HD7: =ABS(DD7) -> 0.5033889 | HE7: =ABS(DE7) -> 0.50598305 | ... KS7: =ABS(GS7) -> 0.29850979
A8: -1.2695076 | B8: -1.2220391 | C8: 0.19808519 | D8: -1.6478444 | E8: 0.1675735 | F8: -0.035489094 | G8: 0.50151621 | H8: 1.4955332 | I8: 0.077937508 | J8: 0.061521782 | K8: 0.51660376 | L8: 0.27637943 | M8: 0.070598624 | N8: -1.1090849 | O8: 0.54506601 | P8: -0.94440268 | Q8: -0.29182386 | R8: 0.22646985 | S8: -0.61013144 | T8: 0.79332936 | U8: -0.82048742 | V8: 0.21674513 | W8: -1.7089392 | X8: -1.0601728 | Y8: 0.54264896 | Z8: 0.22845751 | AA8: -0.68436762 | AB8: -1.0561522 | AC8: -0.63636674 | AD8: 0.67439043 | AE8: -0.86296206 | AF8: -0.96686813 | AG8: 0.90096686 | AH8: -0.03368527 | AI8: 1.1632938 | AJ8: 0.92400946 | AK8: 1.5610199 | AL8: -0.28374164 | AM8: -0.8871454 | AN8: 0.99451468 | AO8: 0.78162189 | AP8: 0.152108 | AQ8: -0.045322915 | AR8: -0.32071921 | AS8: 0.79418162 | AT8: 0.40936656 | AU8: 2.1829384 | AV8: -1.8848885 | AW8: -2.6108998 | AX8: -0.1775669 | AY8: -2.1399372 | AZ8: 1.1480412 | BA8: -0.70518188 | BB8: 1.4866434 | BC8: 1.3873807 | BD8: 0.3248563 | BE8: 1.7006899 | BF8: 0.11544242 | BG8: 1.0082498 | BH8: -0.0040986376 | BI8: 0.6462094 | BJ8: 0.22721219 | BK8: 0.2306341 | BL8: -0.032602602 | BM8: 1.127855 | BN8: -0.67302825 | BO8: -0.89308468 | BP8: 0.92127129 | BQ8: 0.67751981 | BR8: -0.46064741 | BS8: 0.30992516 | BT8: 0.2623437 | BU8: 1.3172474 | BV8: 1.1932784 | BW8: 1.1293903 | BX8: 1.5682503 | BY8: 0.50215651 | BZ8: 1.5975613 | CA8: 1.3785523 | CB8: 1.0953972 | CC8: 2.7030091 | CD8: -0.038164531 | CE8: 0.10347137 | CF8: 0.44591645 | CG8: -1.2159908 | CH8: -0.32786869 | CI8: 0.39365619 | CJ8: -0.33463405 | CK8: 1.6757575 | CL8: -0.035834416 | CM8: -0.035497712 | CN8: -0.61173305 | CO8: -0.33927276 | CP8: 1.1710582 | CQ8: -1.1768647 | CR8: 0.18099344 | CS8: 0.2359619 | CT8: 0.3114985 | CU8: -0.56401232 | CV8: 0.31993341 | CX8: =A8-A64 -> -2.2682709 | CY8: =B8-B64 -> -0.98582669 | CZ8: =C8-C64 -> -0.55036473 | DA8: =D8-D64 -> -1.7377795 | DB8: =E8-E64 -> -0.045011025 | DC8: =F8-F64 -> -0.11693873 | DD8: =G8-G64 -> -0.050437658 | DE8: =H8-H64 -> 1.3178741 | ... GS8: =CV8-CV64 -> 0.48195186 | GX8: =ABS(CX8) -> 2.2682709 | GY8: =ABS(CY8) -> 0.98582669 | GZ8: =ABS(CZ8) -> 0.55036473 | HA8: =ABS(DA8) -> 1.7377795 | HB8: =ABS(DB8) -> 0.045011025 | HC8: =ABS(DC8) -> 0.11693873 | HD8: =ABS(DD8) -> 0.050437658 | HE8: =ABS(DE8) -> 1.3178741 | ... KS8: =ABS(GS8) -> 0.48195186
A9: -1.1559773 | B9: 0.051641086 | C9: 2.608251 | D9: -0.72985262 | E9: -0.29576541 | F9: 0.2132659 | G9: -0.48571784 | H9: -1.6369026 | I9: 1.1289014 | J9: -0.89246724 | K9: -1.1240904 | L9: 0.81188583 | M9: 0.33718364 | N9: 1.5361992 | O9: -0.68316797 | P9: -1.02171 | Q9: 0.42037762 | R9: 0.27288976 | S9: -0.9607998 | T9: 0.23619611 | U9: 1.4353981 | V9: -0.62654527 | W9: 1.1205909 | X9: 1.2460575 | Y9: -0.11153197 | Z9: -0.8157762 | AA9: -0.71581781 | AB9: -0.29944873 | AC9: -1.1991125 | AD9: -1.8672726 | AE9: 0.36671865 | AF9: 0.77531037 | AG9: -0.77322596 | AH9: 0.9310625 | AI9: -1.0295041 | AJ9: -0.49149801 | AK9: -2.3243642 | AL9: -1.8650732 | AM9: 0.092440868 | AN9: 0.38507375 | AO9: -0.52683582 | AP9: 0.064125481 | AQ9: -1.7330434 | AR9: 0.48318841 | AS9: 1.3078508 | AT9: 1.4653596 | AU9: -1.6613406 | AV9: -1.5154553 | AW9: 2.0791727 | AX9: -0.30011178 | AY9: 0.29468919 | AZ9: -0.63484493 | BA9: -0.82985593 | BB9: -1.0987399 | BC9: 0.7040187 | BD9: -0.43520417 | BE9: -2.0780123 | BF9: -0.60230868 | BG9: -0.062893972 | BH9: 0.097491373 | BI9: 1.9123655 | BJ9: 0.32427224 | BK9: 0.33702876 | BL9: -1.376938 | BM9: -0.48927696 | BN9: -0.80115648 | BO9: -0.98227465 | BP9: 1.644272 | BQ9: 0.17608069 | BR9: -0.7092728 | BS9: -1.2021864 | BT9: -4.0982893 | BU9: -0.11553181 | BV9: -1.4588376 | BW9: -1.7299796 | BX9: -0.74895332 | BY9: -0.45378172 | BZ9: -1.8594075 | CA9: -1.4370107 | CB9: -0.85861988 | CC9: -0.25283476 | CD9: 0.54830808 | CE9: -0.79024964 | CF9: 2.0400723 | CG9: 0.63908629 | CH9: 2.0757032 | CI9: 0.39640626 | CJ9: 1.499319 | CK9: -1.2368427 | CL9: -0.1640231 | CM9: 0.62744879 | CN9: 0.52860492 | CO9: -0.36045211 | CP9: -1.8091023 | CQ9: 1.4572288 | CR9: 0.18227395 | CS9: 1.4223672 | CT9: -0.82411962 | CU9: -0.30197324 | CV9: 0.70737109 | CX9: =A9-A65 -> 0.11353035 | CY9: =B9-B65 -> 1.2736802 | CZ9: =C9-C65 -> 2.4101658 | DA9: =D9-D65 -> 0.91799179 | DB9: =E9-E65 -> -0.46333891 | DC9: =F9-F65 -> 0.24875499 | DD9: =G9-G65 -> -0.98723405 | DE9: =H9-H65 -> -3.1324358 | ... GS9: =CV9-CV65 -> 0.38743768 | GX9: =ABS(CX9) -> 0.11353035 | GY9: =ABS(CY9) -> 1.2736802 | GZ9: =ABS(CZ9) -> 2.4101658 | HA9: =ABS(DA9) -> 0.91799179 | HB9: =ABS(DB9) -> 0.46333891 | HC9: =ABS(DC9) -> 0.24875499 | HD9: =ABS(DD9) -> 0.98723405 | HE9: =ABS(DE9) -> 3.1324358 | ... KS9: =ABS(GS9) -> 0.38743768
A10: 0.21483594 | B10: 0.82877878 | C10: -1.5731715 | D10: -0.31689196 | E10: 0.40138457 | F10: 0.46113338 | G10: -0.62409434 | H10: -0.29699858 | I10: -0.0094892645 | J10: 0.050452744 | K10: 1.6171442 | L10: 0.28679675 | M10: 0.16552526 | N10: -0.72291043 | O10: 0.97878831 | P10: -1.1655104 | Q10: -1.0903372 | R10: -0.052281054 | S10: 0.46469975 | T10: 0.10707231 | U10: -2.1606036 | V10: 0.82632576 | W10: -0.49892617 | X10: -1.6591308 | Y10: 1.9209154 | Z10: -1.255479 | AA10: -0.50207083 | AB10: 2.1421539 | AC10: 0.30928654 | AD10: 1.3982046 | AE10: 0.69549698 | AF10: -1.5431828 | AG10: 0.79104107 | AH10: 0.69183454 | AI10: -0.40184212 | AJ10: -1.2791702 | AK10: 1.7425967 | AL10: 1.1398921 | AM10: 0.89146165 | AN10: 1.2879554 | AO10: 0.21494243 | AP10: -0.31651048 | AQ10: -0.9045467 | AR10: 0.43408662 | AS10: -0.11661941 | AT10: -1.5757079 | AU10: 1.0509644 | AV10: 1.7492366 | AW10: -0.019567093 | AX10: 0.99645332 | AY10: -0.58048252 | AZ10: 0.59888822 | BA10: -1.1946369 | BB10: -1.0346078 | BC10: 0.92288019 | BD10: 1.3728753 | BE10: 1.1595081 | BF10: -1.3327843 | BG10: 0.33785066 | BH10: -0.19070109 | BI10: 1.0639396 | BJ10: 0.76782382 | BK10: 2.3412744 | BL10: 1.672576 | BM10: -1.6633848 | BN10: 1.1648453 | BO10: -1.9167634 | BP10: 0.35441904 | BQ10: 0.87895532 | BR10: 1.1484105 | BS10: -0.056994432 | BT10: 0.88453697 | BU10: -0.032924676 | BV10: -0.62070937 | BW10: -1.2082288 | BX10: 1.1842502 | BY10: 1.7450651 | BZ10: 2.0756846 | CA10: -0.74212904 | CB10: -0.66936394 | CC10: -0.27948455 | CD10: 0.13060897 | CE10: -0.23354639 | CF10: -0.10238113 | CG10: -2.5267283 | CH10: -0.21730144 | CI10: 1.3042291 | CJ10: -2.4349935 | CK10: 1.9974612 | CL10: -0.95973851 | CM10: -1.9368212 | CN10: 1.2003745 | CO10: -1.0491234 | CP10: 0.17116681 | CQ10: -0.80044843 | CR10: 0.45250249 | CS10: 0.97543745 | CT10: 0.22540677 | CU10: 0.35860439 | CV10: -0.41749935 | CX10: =A10-A66 -> 1.3708132 | CY10: =B10-B66 -> 0.7771377 | CZ10: =C10-C66 -> -4.1814225 | DA10: =D10-D66 -> 0.41296066 | DB10: =E10-E66 -> 0.69714998 | DC10: =F10-F66 -> 0.24786748 | DD10: =G10-G66 -> -0.1383765 | DE10: =H10-H66 -> 1.339904 | ... GS10: =CV10-CV66 -> -1.1248704 | GX10: =ABS(CX10) -> 1.3708132 | GY10: =ABS(CY10) -> 0.7771377 | GZ10: =ABS(CZ10) -> 4.1814225 | HA10: =ABS(DA10) -> 0.41296066 | HB10: =ABS(DB10) -> 0.69714998 | HC10: =ABS(DC10) -> 0.24786748 | HD10: =ABS(DD10) -> 0.1383765 | HE10: =ABS(DE10) -> 1.339904 | ... KS10: =ABS(GS10) -> 1.1248704
A11: -0.45059274 | B11: -0.049731192 | C11: 1.5707391 | D11: -0.68438291 | E11: 0.095908971 | F11: -0.28353942 | G11: 1.1728726 | H11: 0.84617935 | I11: 1.8216667 | J11: 0.56962841 | K11: -1.9520036 | L11: 1.8975821 | M11: -0.046750695 | N11: 0.07378374 | O11: 0.20629062 | P11: -0.56773173 | Q11: -0.57450462 | R11: 0.96647449 | S11: -1.3492972 | T11: 0.26860689 | U11: 0.86261602 | V11: 1.9864982 | W11: 1.4917618 | X11: -0.24291891 | Y11: -1.0547886 | Z11: -0.066217742 | AA11: 0.95635903 | AB11: -0.67168923 | AC11: 0.66188228 | AD11: 0.06581144 | AE11: -0.19804337 | AF11: -0.39065691 | AG11: 0.37564004 | AH11: -0.24332758 | AI11: -1.1737951 | AJ11: 0.2021501 | AK11: 0.91349457 | AL11: -0.62474682 | AM11: -0.30502793 | AN11: -0.55375527 | AO11: -0.88104359 | AP11: 0.14752698 | AQ11: 0.58971552 | AR11: 0.19091391 | AS11: 0.62232759 | AT11: 0.81464568 | AU11: -0.64671077 | AV11: 0.73121153 | AW11: -0.57564961 | AX11: -0.23183973 | AY11: -0.81963984 | AZ11: 0.74325448 | BA11: 0.68510257 | BB11: 1.2663278 | BC11: 0.53525128 | BD11: -0.84090524 | BE11: 0.43042455 | BF11: 1.2643665 | BG11: -0.60208693 | BH11: -0.25628068 | BI11: 1.3552365 | BJ11: 1.3128058 | BK11: -1.4093406 | BL11: -2.0218553 | BM11: 0.36341995 | BN11: -2.1067306 | BO11: 0.10514831 | BP11: 0.97286939 | BQ11: -2.3111561 | BR11: 0.91529141 | BS11: 1.3237149 | BT11: -0.60379952 | BU11: 0.74218387 | BV11: 1.3284874 | BW11: -1.2523972 | BX11: -1.1219976 | BY11: -0.33965464 | BZ11: -0.29447349 | CA11: 0.75453758 | CB11: 0.29271676 | CC11: 0.8408595 | CD11: -0.47501682 | CE11: 1.5831168 | CF11: 0.51924104 | CG11: -0.19610908 | CH11: 0.42605692 | CI11: -0.71159538 | CJ11: 0.83666272 | CK11: -1.6001648 | CL11: 0.77740974 | CM11: -0.21409852 | CN11: -1.0841628 | CO11: 1.2909636 | CP11: -0.48402581 | CQ11: 0.69293218 | CR11: -0.59874999 | CS11: -0.72714686 | CT11: -1.4493048 | CU11: -0.75683907 | CV11: 0.46500697 | CX11: =A11-A67 -> -0.66542868 | CY11: =B11-B67 -> -0.87850997 | CZ11: =C11-C67 -> 3.1439106 | DA11: =D11-D67 -> -0.36749096 | DB11: =E11-E67 -> -0.3054756 | DC11: =F11-F67 -> -0.7446728 | DD11: =G11-G67 -> 1.7969669 | DE11: =H11-H67 -> 1.1431779 | ... GS11: =CV11-CV67 -> 0.88250632 | GX11: =ABS(CX11) -> 0.66542868 | GY11: =ABS(CY11) -> 0.87850997 | GZ11: =ABS(CZ11) -> 3.1439106 | HA11: =ABS(DA11) -> 0.36749096 | HB11: =ABS(DB11) -> 0.3054756 | HC11: =ABS(DC11) -> 0.7446728 | HD11: =ABS(DD11) -> 1.7969669 | HE11: =ABS(DE11) -> 1.1431779 | ... KS11: =ABS(GS11) -> 0.88250632
A12: 1.2892844 | B12: 0.55958756 | C12: 0.55889318 | D12: 0.60308134 | E12: 0.45247978 | F12: -0.50742593 | G12: 0.24766462 | H12: -0.2831593 | I12: -1.7592269 | J12: -0.35626485 | K12: 0.98603759 | L12: -0.12082155 | M12: -1.1610305 | N12: -2.2021514 | O12: -0.90587612 | P12: 0.79718556 | Q12: -0.53762854 | R12: -0.082078613 | S12: 1.4785351 | T12: -1.3625565 | U12: 0.44669831 | V12: -0.9756187 | W12: -0.85454553 | X12: -0.771689 | Y12: -0.337608 | Z12: -1.0133246 | AA12: 0.31657518 | AB12: -0.03784573 | AC12: -0.96165798 | AD12: -0.2465178 | AE12: 0.88397366 | AF12: 0.96472297 | AG12: 0.39636107 | AH12: 0.31983573 | AI12: 0.88954593 | AJ12: 0.46322502 | AK12: 0.80615435 | AL12: -0.41903323 | AM12: -1.7842457 | AN12: -0.66984262 | AO12: 0.27357757 | AP12: -0.88710598 | AQ12: -0.2091489 | AR12: 0.038919119 | AS12: -1.0222889 | AT12: -0.041589852 | AU12: -0.076710155 | AV12: -0.34655172 | AW12: -0.92209952 | AX12: 1.8162626 | AY12: -0.9669244 | AZ12: -0.33354582 | BA12: -0.081702895 | BB12: 0.41838026 | BC12: -0.34742503 | BD12: -0.42146897 | BE12: 0.15991875 | BF12: -1.2115098 | BG12: -0.2340514 | BH12: -1.8655731 | BI12: 0.057299632 | BJ12: -1.9089837 | BK12: -0.67823535 | BL12: 2.0429822 | BM12: 0.90407317 | BN12: 1.2873201 | BO12: -1.6900246 | BP12: -0.044969872 | BQ12: 1.0802899 | BR12: 0.52292915 | BS12: -0.21156041 | BT12: 1.3711452 | BU12: -2.6392999 | BV12: 0.31428732 | BW12: 1.0586201 | BX12: 0.68257638 | BY12: 1.1187167 | BZ12: 0.51370219 | CA12: -0.55395709 | CB12: 0.86676761 | CC12: -1.7635369 | CD12: -1.00399 | CE12: -0.82523184 | CF12: 0.44651022 | CG12: 1.465257 | CH12: -0.092505421 | CI12: 0.29668533 | CJ12: -0.18306478 | CK12: 0.24385612 | CL12: -0.0078289183 | CM12: 1.2199101 | CN12: -0.95088258 | CO12: -1.5579022 | CP12: 0.36872527 | CQ12: -0.74240858 | CR12: -0.62758269 | CS12: 0.62329389 | CT12: 0.14173664 | CU12: -0.027126286 | CV12: 1.4426437 | CX12: =A12-A68 -> 1.7398772 | CY12: =B12-B68 -> 0.60931875 | CZ12: =C12-C68 -> -1.0118459 | DA12: =D12-D68 -> 1.2874643 | DB12: =E12-E68 -> 0.35657081 | DC12: =F12-F68 -> -0.2238865 | DD12: =G12-G68 -> -0.92520798 | DE12: =H12-H68 -> -1.1293386 | ... GS12: =CV12-CV68 -> 0.97763677 | GX12: =ABS(CX12) -> 1.7398772 | GY12: =ABS(CY12) -> 0.60931875 | GZ12: =ABS(CZ12) -> 1.0118459 | HA12: =ABS(DA12) -> 1.2874643 | HB12: =ABS(DB12) -> 0.35657081 | HC12: =ABS(DC12) -> 0.2238865 | HD12: =ABS(DD12) -> 0.92520798 | HE12: =ABS(DE12) -> 1.1293386 | ... KS12: =ABS(GS12) -> 0.97763677
A13: 0.029143598 | B13: 0.77418507 | C13: 0.47850063 | D13: -0.54446061 | E13: -1.3669594 | F13: 0.12632871 | G13: 0.13458389 | H13: 0.23954025 | I13: 0.16414538 | J13: 0.76805111 | K13: 0.10778315 | L13: -1.5335938 | M13: -0.6549018 | N13: 0.40803728 | O13: -2.9227666 | P13: 0.16045921 | Q13: 0.56898992 | R13: 0.082615653 | S13: -1.0094338 | T13: 0.20171024 | U13: 1.2486299 | V13: 0.89260486 | W13: 1.1602224 | X13: -0.35056906 | Y13: -0.94254396 | Z13: 1.5824822 | AA13: 0.5493067 | AB13: -1.4776284 | AC13: 0.76231376 | AD13: -1.1768745 | AE13: -0.91963923 | AF13: -0.62326763 | AG13: -0.014124902 | AH13: -0.3438278 | AI13: -0.49705348 | AJ13: 1.3003316 | AK13: -0.47192336 | AL13: 0.0970455 | AM13: -0.27738668 | AN13: 1.0623698 | AO13: -0.97226994 | AP13: 1.06717 | AQ13: 0.31361597 | AR13: -0.69806118 | AS13: 0.78769186 | AT13: 1.369284 | AU13: -1.5293532 | AV13: -0.44079969 | AW13: 0.80324114 | AX13: -1.6747251 | AY13: -0.027096456 | AZ13: -0.73175713 | BA13: -1.6385471 | BB13: 0.77213524 | BC13: -0.010782313 | BD13: 0.682684 | BE13: 0.69364602 | BF13: 0.20442314 | BG13: -0.030096866 | BH13: -0.77574411 | BI13: -0.80899945 | BJ13: -0.7352811 | BK13: -0.10436245 | BL13: -1.5352358 | BM13: 2.2706191 | BN13: -1.6793568 | BO13: -0.081263546 | BP13: -0.87623004 | BQ13: -0.015619529 | BR13: 0.46172627 | BS13: -0.72478085 | BT13: 0.039337706 | BU13: 2.3038958 | BV13: 0.34008039 | BW13: -1.2569595 | BX13: -0.97674315 | BY13: 1.3355139 | BZ13: -2.5233856 | CA13: 2.620541 | CB13: -0.56256515 | CC13: -0.071859995 | CD13: 0.4486891 | CE13: 0.58865853 | CF13: -0.21941151 | CG13: 0.70334279 | CH13: -0.18621938 | CI13: 0.58138244 | CJ13: 0.18558241 | CK13: -1.4979151 | CL13: -0.87470419 | CM13: 0.57346657 | CN13: 0.22404748 | CO13: 1.4899894 | CP13: -1.047838 | CQ13: -1.5031598 | CR13: -1.259427 | CS13: -1.2810651 | CT13: 0.69026389 | CU13: -1.8793078 | CV13: -0.57128058 | CX13: =A13-A69 -> -1.2601408 | CY13: =B13-B69 -> 0.21459751 | CZ13: =C13-C69 -> -0.080392548 | DA13: =D13-D69 -> -1.147542 | DB13: =E13-E69 -> -1.8194392 | DC13: =F13-F69 -> 0.63375464 | DD13: =G13-G69 -> -0.11308073 | DE13: =H13-H69 -> 0.52269955 | ... GS13: =CV13-CV69 -> -2.0139243 | GX13: =ABS(CX13) -> 1.2601408 | GY13: =ABS(CY13) -> 0.21459751 | GZ13: =ABS(CZ13) -> 0.080392548 | HA13: =ABS(DA13) -> 1.147542 | HB13: =ABS(DB13) -> 1.8194392 | HC13: =ABS(DC13) -> 0.63375464 | HD13: =ABS(DD13) -> 0.11308073 | HE13: =ABS(DE13) -> 0.52269955 | ... KS13: =ABS(GS13) -> 2.0139243
A14: -0.47677712 | B14: 0.23326306 | C14: -0.36843244 | D14: -0.11180591 | E14: 0.68736747 | F14: 0.55934645 | G14: 0.42876593 | H14: 0.46456552 | I14: -0.72378693 | J14: -0.45835882 | K14: -1.1825984 | L14: -0.52376025 | M14: 0.67413978 | N14: -2.0027585 | O14: 0.1578482 | P14: 0.052220173 | Q14: -0.63605171 | R14: 1.4780877 | S14: 1.8722237 | T14: 0.82395064 | U14: 0.17706064 | V14: -0.51532482 | W14: 1.877675 | X14: -0.36912114 | Y14: -0.24673073 | Z14: -1.7155715 | AA14: 0.55939297 | AB14: -0.40143889 | AC14: -0.73403187 | AD14: -0.55965697 | AE14: -0.71135691 | AF14: -0.14419954 | AG14: 0.76597503 | AH14: 0.077516727 | AI14: 2.2806422 | AJ14: 0.85379068 | AK14: 0.73678862 | AL14: -2.2748092 | AM14: 0.93527265 | AN14: 1.1414997 | AO14: -0.34044515 | AP14: 1.4038746 | AQ14: 0.62585892 | AR14: -0.70357525 | AS14: -0.14224809 | AT14: 0.064159364 | AU14: -1.4273252 | AV14: 2.9500318 | AW14: -0.1920949 | AX14: 1.341917 | AY14: -0.0080626848 | AZ14: 1.441381 | BA14: 0.32115036 | BB14: 0.22686777 | BC14: 0.13198755 | BD14: 1.422811 | BE14: 0.99345313 | BF14: 0.33372714 | BG14: -0.45282359 | BH14: 0.61838813 | BI14: -0.41328696 | BJ14: -0.36872074 | BK14: -0.47268502 | BL14: 0.79259236 | BM14: 0.37813282 | BN14: 1.4860647 | BO14: 0.97863714 | BP14: 1.799447 | BQ14: -2.7495151 | BR14: -0.5346259 | BS14: -0.7403363 | BT14: -0.80510659 | BU14: -0.19593165 | BV14: -0.10376053 | BW14: 1.3468467 | BX14: 0.5373352 | BY14: -1.9204052 | BZ14: 1.1048598 | CA14: 0.17792979 | CB14: 0.18074267 | CC14: -0.84781502 | CD14: -0.80756005 | CE14: -0.61522444 | CF14: -0.96706981 | CG14: -0.022024476 | CH14: 1.4226291 | CI14: 0.5311154 | CJ14: -1.3911808 | CK14: 0.76133502 | CL14: 0.28542133 | CM14: -0.1494426 | CN14: 0.092954404 | CO14: 0.61563715 | CP14: 0.14459301 | CQ14: 0.087850231 | CR14: 1.6699459 | CS14: 0.9053867 | CT14: -0.29005878 | CU14: 2.3914161 | CV14: 0.90930173 | CX14: =A14-A70 -> -0.50592071 | CY14: =B14-B70 -> -0.54092201 | CZ14: =C14-C70 -> -0.84693308 | DA14: =D14-D70 -> 0.43265471 | DB14: =E14-E70 -> 2.0543269 | DC14: =F14-F70 -> 0.43301774 | DD14: =G14-G70 -> 0.29418204 | DE14: =H14-H70 -> 0.22502526 | ... GS14: =CV14-CV70 -> 1.4805823 | GX14: =ABS(CX14) -> 0.50592071 | GY14: =ABS(CY14) -> 0.54092201 | GZ14: =ABS(CZ14) -> 0.84693308 | HA14: =ABS(DA14) -> 0.43265471 | HB14: =ABS(DB14) -> 2.0543269 | HC14: =ABS(DC14) -> 0.43301774 | HD14: =ABS(DD14) -> 0.29418204 | HE14: =ABS(DE14) -> 0.22502526 | ... KS14: =ABS(GS14) -> 1.4805823
A15: -1.0290332 | B15: -0.73386634 | C15: 0.44704662 | D15: -0.71932754 | E15: -0.17207779 | F15: -1.2254388 | G15: -0.64563322 | H15: 0.23888909 | I15: 0.82618258 | J15: 1.2182004 | K15: 0.50467897 | L15: 1.6019556 | M15: 0.29433359 | N15: 0.80084624 | O15: 0.42564958 | P15: -0.23731129 | Q15: 0.18473995 | R15: 1.0627853 | S15: -0.7345364 | T15: -0.18323984 | U15: -0.82000533 | V15: -0.074860676 | W15: 0.0014919741 | X15: 0.15040803 | Y15: 0.19390607 | Z15: 1.8034315 | AA15: -0.20391825 | AB15: -0.08838453 | AC15: -0.3323029 | AD15: 1.6272261 | AE15: 1.3111917 | AF15: -0.53645004 | AG15: 0.074595401 | AH15: -0.061697804 | AI15: 0.35041511 | AJ15: 0.12165781 | AK15: 0.75584977 | AL15: 0.25100169 | AM15: -0.1758239 | AN15: -0.50866233 | AO15: 1.0577216 | AP15: -0.81668811 | AQ15: -0.53320094 | AR15: -1.2442696 | AS15: 1.0063763 | AT15: 0.78238268 | AU15: -1.6972107 | AV15: -1.9294635 | AW15: 0.31871548 | AX15: -0.62900895 | AY15: 0.55851119 | AZ15: -1.0071112 | BA15: 0.81484107 | BB15: 1.4256613 | BC15: 0.14785138 | BD15: 0.092705411 | BE15: 0.11870227 | BF15: 0.85147602 | BG15: 0.23098896 | BH15: -2.29332 | BI15: -0.085415024 | BJ15: -0.64911024 | BK15: 0.82146195 | BL15: 0.50088035 | BM15: -1.1141138 | BN15: -0.35397322 | BO15: 0.53374954 | BP15: -1.0667852 | BQ15: -0.49204277 | BR15: 1.0289873 | BS15: 0.70903298 | BT15: -0.19020624 | BU15: 2.2422881 | BV15: -0.17417379 | BW15: -1.5934342 | BX15: -1.2821709 | BY15: 2.1898397 | BZ15: 2.1088321 | CA15: 0.25081206 | CB15: -0.82481595 | CC15: -0.86876635 | CD15: -0.67852447 | CE15: -0.045074663 | CF15: 1.3932369 | CG15: 0.46086662 | CH15: -0.72984338 | CI15: -0.1953212 | CJ15: -0.34787631 | CK15: -0.94626768 | CL15: 0.52283089 | CM15: 0.14837423 | CN15: -0.98817152 | CO15: 0.3024548 | CP15: 0.33514498 | CQ15: 0.42974021 | CR15: 1.2290687 | CS15: -1.1265471 | CT15: -0.52276875 | CU15: -2.0188856 | CV15: -0.0052823885 | CX15: =A15-A71 -> -0.55225604 | CY15: =B15-B71 -> -0.9671294 | CZ15: =C15-C71 -> 0.81547907 | DA15: =D15-D71 -> -0.60752163 | DB15: =E15-E71 -> -0.85944526 | DC15: =F15-F71 -> -1.7847853 | DD15: =G15-G71 -> -1.0743992 | DE15: =H15-H71 -> -0.22567643 | ... GS15: =CV15-CV71 -> -0.91458412 | GX15: =ABS(CX15) -> 0.55225604 | GY15: =ABS(CY15) -> 0.9671294 | GZ15: =ABS(CZ15) -> 0.81547907 | HA15: =ABS(DA15) -> 0.60752163 | HB15: =ABS(DB15) -> 0.85944526 | HC15: =ABS(DC15) -> 1.7847853 | HD15: =ABS(DD15) -> 1.0743992 | HE15: =ABS(DE15) -> 0.22567643 | ... KS15: =ABS(GS15) -> 0.91458412
... A51: -0.056380255 | B51: 0.6801278 | C51: -0.98300017 | D51: -1.3814463 | E51: 0.99873524 | F51: 0.2895731 | G51: -0.77910079 | H51: 0.53004109 | I51: -0.62805108 | J51: -2.1899733 | K51: 1.0921708 | L51: 0.021413238 | M51: -0.45064543 | N51: 1.8513009 | O51: -0.96610634 | P51: 0.12302305 | Q51: 0.89606646 | R51: 0.18631981 | S51: -0.20625531 | T51: 0.29900039 | U51: -0.087816867 | V51: 0.74573491 | W51: 0.27138074 | X51: 0.7135849 | Y51: 3.2002173 | Z51: -1.6097531 | AA51: 0.14324921 | AB51: -1.3419132 | AC51: 0.46631732 | AD51: 1.7331959 | AE51: 1.7311894 | AF51: -0.77949494 | AG51: 0.3862635 | AH51: 0.93053705 | AI51: 0.5639796 | AJ51: 0.58356892 | AK51: -1.7532942 | AL51: -0.67390006 | AM51: 0.20868882 | AN51: -0.86956748 | AO51: -0.82706514 | AP51: -0.31296479 | AQ51: 1.2894217 | AR51: 0.58122014 | AS51: 0.84457067 | AT51: 0.67683792 | AU51: 0.82414129 | AV51: -0.19362402 | AW51: -1.6550069 | AX51: 0.49578571 | AY51: 0.8519493 | AZ51: 1.4947022 | BA51: -1.2932376 | BB51: -0.40494038 | BC51: 1.6519457 | BD51: 0.063606828 | BE51: -0.93982844 | BF51: -1.3884156 | BG51: 0.25933507 | BH51: -0.80231657 | BI51: 0.046169977 | BJ51: 1.5144503 | BK51: 0.96470315 | BL51: 1.1214204 | BM51: -0.90620824 | BN51: 1.5459684 | BO51: -0.42251848 | BP51: 0.67401039 | BQ51: 1.0505963 | BR51: 1.0767397 | BS51: -0.07984901 | BT51: -1.292822 | BU51: -0.46896602 | BV51: -0.0064583634 | BW51: -0.27217142 | BX51: 1.1463305 | BY51: -1.6377764 | BZ51: 0.89356864 | CA51: 0.48998225 | CB51: -0.14408568 | CC51: -0.18636137 | CD51: 1.2593915 | CE51: 0.51420465 | CF51: -0.84003335 | CG51: 0.86639604 | CH51: -2.2336729 | CI51: -0.52299434 | CJ51: -0.54255662 | CK51: 0.11477063 | CL51: -0.76753497 | CM51: -1.036261 | CN51: -0.73192844 | CO51: -0.39318274 | CP51: -1.8761129 | CQ51: 0.92686811 | CR51: -0.87579567 | CS51: -2.7152653 | CT51: -0.19548795 | CU51: -2.0287873 | CV51: 0.14785456 | CX51: =A51-A107 -> -0.26783361 | CY51: =B51-B107 -> 0.78865703 | CZ51: =C51-C107 -> -0.75559964 | DA51: =D51-D107 -> -1.2536973 | DB51: =E51-E107 -> 1.1718157 | DC51: =F51-F107 -> 0.86643252 | DD51: =G51-G107 -> 0.23187395 | DE51: =H51-H107 -> 2.3088496 | ... GS51: =CV51-CV107 -> 1.6280712 | GX51: =ABS(CX51) -> 0.26783361 | GY51: =ABS(CY51) -> 0.78865703 | GZ51: =ABS(CZ51) -> 0.75559964 | HA51: =ABS(DA51) -> 1.2536973 | HB51: =ABS(DB51) -> 1.1718157 | HC51: =ABS(DC51) -> 0.86643252 | HD51: =ABS(DD51) -> 0.23187395 | HE51: =ABS(DE51) -> 2.3088496 | ... KS51: =ABS(GS51) -> 1.6280712
A53: prognozy
A58: -0.57397318 | B58: -0.80199798 | C58: -0.64338313 | D58: -0.45611994 | E58: -0.65037341 | F58: -1.9984193 | G58: -0.88070713 | H58: 0.48879108 | I58: -0.83820545 | J58: -2.1194027 | K58: -1.1299384 | L58: -0.36683943 | M58: 0.7284184 | N58: -0.20845647 | O58: 0.059839233 | P58: 0.56552629 | Q58: 0.26649361 | R58: 0.4946153 | S58: 0.59332793 | T58: 0.92260105 | U58: -0.43282123 | V58: 0.26391875 | W58: 0.11986578 | X58: -0.029524829 | Y58: -2.0067562 | Z58: 1.3945705 | AA58: 0.059123505 | AB58: 0.8022 | AC58: 1.394069 | AD58: -0.46882782 | AE58: 2.0634901 | AF58: 1.2006446 | AG58: 0.25611851 | AH58: 0.72234101 | AI58: 2.2471124 | AJ58: 0.61484332 | AK58: -0.74837345 | AL58: 0.64027714 | AM58: 0.59386024 | AN58: -0.828579 | AO58: 1.5993398 | AP58: -2.5193546 | AQ58: 0.73011514 | AR58: 2.633068 | AS58: -0.52481782 | AT58: 0.87210583 | AU58: 0.26374456 | AV58: 0.012645746 | AW58: 0.54895666 | AX58: -2.5430861 | AY58: 0.86109625 | AZ58: 0.9601052 | BA58: -0.13989967 | BB58: -0.98353463 | BC58: -0.51995667 | BD58: 0.60747135 | BE58: 0.10029896 | BF58: -0.52907767 | BG58: 0.54440257 | BH58: -0.31308713 | BI58: -0.23019691 | BJ58: 0.94245692 | BK58: -0.49404876 | BL58: 1.2956774 | BM58: 0.30281547 | BN58: 0.13226668 | BO58: -2.6610844 | BP58: 1.8599992 | BQ58: -0.50529353 | BR58: -0.12012686 | BS58: 1.0035527 | BT58: -0.35540948 | BU58: 0.74138259 | BV58: 0.38881856 | BW58: -0.61310761 | BX58: -0.59886175 | BY58: 0.001927725 | BZ58: 0.81521042 | CA58: 1.1515037 | CB58: 0.530256 | CC58: 0.053947222 | CD58: -0.85472986 | CE58: 0.0440331 | CF58: 1.0112553 | CG58: -0.16200474 | CH58: -0.30508254 | CI58: -0.082548576 | CJ58: -0.75410244 | CK58: 0.23556602 | CL58: -0.39841542 | CM58: 2.2969228 | CN58: -1.0881345 | CO58: -0.68374486 | CP58: -0.095319342 | CQ58: 0.10940608 | CR58: 1.492096 | CS58: -0.50617541 | CT58: -0.20399968 | CU58: -0.24084563 | CV58: -0.037174807
A59: 1.0045752 | B59: 0.86045762 | C59: 1.8698138 | D59: -2.1050089 | E59: 1.4475623 | F59: -1.0252553 | G59: 0.67223197 | H59: -0.12593962 | I59: 0.66403577 | J59: 0.48728257 | K59: 1.290437 | L59: -0.10407828 | M59: -1.3697692 | N59: -0.94641923 | O59: -0.0023437728 | P59: 1.3802507 | Q59: -1.0370113 | R59: -0.030391357 | S59: 0.74253305 | T59: -0.53145641 | U59: -1.1101401 | V59: -0.82296607 | W59: 1.0494791 | X59: -0.65331935 | Y59: 1.7979421 | Z59: 1.3992228 | AA59: -1.5339369 | AB59: -0.042305234 | AC59: 0.12857575 | AD59: -0.013076373 | AE59: 1.2471412 | AF59: -0.67416157 | AG59: -1.0774626 | AH59: -0.23065657 | AI59: 0.098923911 | AJ59: -0.10926624 | AK59: 0.40753701 | AL59: 0.25099561 | AM59: 0.1810706 | AN59: 0.51702964 | AO59: 0.10157248 | AP59: 1.7962585 | AQ59: -2.0613279 | AR59: -1.1304584 | AS59: -0.066769994 | AT59: 0.71444283 | AU59: -1.1715007 | AV59: -1.2605332 | AW59: -0.23999569 | AX59: 0.42370321 | AY59: 0.2509917 | AZ59: 1.2083722 | BA59: -0.61256059 | BB59: 1.7598784 | BC59: -0.96783713 | BD59: 0.81826571 | BE59: -0.30807434 | BF59: -0.33039331 | BG59: -0.23850679 | BH59: 0.63716688 | BI59: 1.7706939 | BJ59: 0.095477389 | BK59: 1.1379093 | BL59: -0.84198992 | BM59: 0.013368058 | BN59: 0.78749319 | BO59: -0.63159279 | BP59: -1.2322297 | BQ59: 0.79350603 | BR59: 0.34769499 | BS59: -0.96262952 | BT59: 1.1503698 | BU59: -1.03384 | BV59: -0.42687992 | BW59: 0.31755047 | BX59: -0.48356092 | BY59: 1.8675054 | BZ59: -0.66249515 | CA59: -0.35457305 | CB59: -0.30536157 | CC59: -0.95470905 | CD59: -0.42355842 | CE59: 0.47222179 | CF59: -0.64173278 | CG59: 1.3009344 | CH59: 0.2840916 | CI59: -0.44328147 | CJ59: -0.19857469 | CK59: -1.2178243 | CL59: -1.4850007 | CM59: -0.57576538 | CN59: 0.14583535 | CO59: 0.67415011 | CP59: 0.32959936 | CQ59: 0.58478148 | CR59: -1.2458844 | CS59: -0.884995 | CT59: -0.47582754 | CU59: -0.96097865 | CV59: 0.12841158
A60: -0.18009008 | B60: -1.3995218 | C60: -1.1065712 | D60: 0.26515134 | E60: -1.5106233 | F60: -0.72579301 | G60: -0.018941789 | H60: -1.364184 | I60: -0.75414951 | J60: 1.1530312 | K60: -0.28910409 | L60: -1.0377032 | M60: 0.35276624 | N60: -0.057459491 | O60: -0.59752539 | P60: -0.54406168 | Q60: -1.3134701 | R60: -1.1236538 | S60: -2.4756209 | T60: -0.93547221 | U60: 0.63002714 | V60: 0.214281 | W60: -0.12213064 | X60: 0.89266895 | Y60: 0.77325208 | Z60: 0.95860215 | AA60: 0.40676258 | AB60: 0.57405627 | AC60: -0.43296252 | AD60: -0.015507445 | AE60: -0.5218363 | AF60: -0.12545251 | AG60: 2.3498354 | AH60: -0.57252497 | AI60: 0.38995911 | AJ60: 0.3497336 | AK60: 1.1452455 | AL60: -1.0909801 | AM60: -1.4844856 | AN60: -1.5964657 | AO60: 0.66834705 | AP60: -1.0871984 | AQ60: 0.75976587 | AR60: 0.99485273 | AS60: 0.7816544 | AT60: -0.090342353 | AU60: 0.10096442 | AV60: 0.58093495 | AW60: -0.025259463 | AX60: -2.5963848 | AY60: -1.2886212 | AZ60: -0.5677279 | BA60: 0.81243667 | BB60: -1.4035666 | BC60: 0.79856109 | BD60: 0.55501781 | BE60: 0.26768604 | BF60: 0.88084358 | BG60: 0.81702522 | BH60: -0.43372653 | BI60: 0.46191722 | BJ60: 0.67816475 | BK60: -0.91124764 | BL60: 0.086291002 | BM60: -0.10709826 | BN60: -0.41788476 | BO60: -0.083762191 | BP60: 0.39812825 | BQ60: 0.13633732 | BR60: -0.037644512 | BS60: 0.079897432 | BT60: 0.013915045 | BU60: -0.63482231 | BV60: 1.0884056 | BW60: -1.3043484 | BX60: 1.0869835 | BY60: -0.30253368 | BZ60: -0.31901241 | CA60: -0.38148891 | CB60: 1.0098949 | CC60: -0.16749578 | CD60: -0.29860421 | CE60: -0.42964982 | CF60: 0.19115581 | CG60: -0.55481318 | CH60: -1.251886 | CI60: -0.75024835 | CJ60: -0.07691277 | CK60: -0.7935302 | CL60: 0.8080841 | CM60: -0.65373048 | CN60: -0.57998171 | CO60: 0.58092369 | CP60: -0.26393276 | CQ60: -0.044161898 | CR60: -0.2454484 | CS60: 0.22118189 | CT60: -0.11840245 | CU60: -0.03947174 | CV60: 0.28381098
A61: 0.71082607 | B61: 1.5167401 | C61: 0.41150468 | D61: 0.36998253 | E61: 0.62535905 | F61: -0.8097624 | G61: -0.17697263 | H61: 0.31614481 | I61: 0.36674015 | J61: 0.17305055 | K61: -0.090686332 | L61: -0.48695115 | M61: -1.247738 | N61: -0.27338663 | O61: 1.2454232 | P61: 0.11142743 | Q61: 0.49482118 | R61: 1.4813385 | S61: 1.6032843 | T61: -0.17371974 | U61: -2.1254313 | V61: -2.3153417 | W61: 1.6513201 | X61: 0.24696982 | Y61: -0.08393172 | Z61: 0.46859397 | AA61: 0.70769619 | AB61: 2.0432101 | AC61: -0.21116124 | AD61: 0.53688984 | AE61: 0.55807678 | AF61: -1.3361494 | AG61: 1.0850432 | AH61: -0.26463723 | AI61: -0.40264002 | AJ61: 0.19970444 | AK61: -0.42504337 | AL61: 0.83172876 | AM61: 3.1543696 | AN61: 1.0022817 | AO61: -0.12562547 | AP61: 0.079844435 | AQ61: -0.1598307 | AR61: -2.6055824 | AS61: -0.88682794 | AT61: -0.28543632 | AU61: -1.5501876 | AV61: -0.55660318 | AW61: -0.066673404 | AX61: 1.2051761 | AY61: -0.27698297 | AZ61: 0.71253322 | BA61: 1.2303401 | BB61: 0.5426154 | BC61: -0.60460652 | BD61: 0.7488549 | BE61: 0.096544966 | BF61: -1.0124995 | BG61: -1.9193298 | BH61: -0.7631593 | BI61: 0.13631066 | BJ61: -0.63526706 | BK61: -1.036477 | BL61: 0.98103377 | BM61: -0.11759196 | BN61: 0.76051477 | BO61: -0.912031 | BP61: -0.079118837 | BQ61: -0.88147065 | BR61: 0.29105508 | BS61: 0.56567904 | BT61: 0.28814457 | BU61: 1.8659941 | BV61: -0.78742117 | BW61: -0.059278462 | BX61: 0.30474776 | BY61: -0.33709964 | BZ61: -0.63478421 | CA61: 0.13766466 | CB61: 1.4648273 | CC61: 0.59950983 | CD61: 1.4652752 | CE61: -0.52407171 | CF61: 0.8540012 | CG61: 0.076054423 | CH61: 0.94267005 | CI61: -0.26441869 | CJ61: -1.3083529 | CK61: 0.86864066 | CL61: -0.49948247 | CM61: 0.34462273 | CN61: -0.41504815 | CO61: -1.6908682 | CP61: 0.45880238 | CQ61: -0.20508334 | CR61: -1.496307 | CS61: -0.81340969 | CT61: -0.64297391 | CU61: 0.36801566 | CV61: -0.35441646
A62: 0.19528307 | B62: 0.070272179 | C62: 2.3307239 | D62: 0.16426452 | E62: -0.00826181 | F62: 1.070545 | G62: 0.18920009 | H62: -1.5271531 | I62: -0.73412803 | J62: 0.26823312 | K62: 0.75564968 | L62: -1.3158187 | M62: -0.2556062 | N62: 1.9705174 | O62: -0.0034363221 | P62: 1.0788113 | Q62: -0.64823831 | R62: -0.20582305 | S62: -0.31956953 | T62: 0.78591218 | U62: 0.76997034 | V62: -0.74746513 | W62: 0.64951353 | X62: 1.7429059 | Y62: -0.36705286 | Z62: -0.28687303 | AA62: -1.2082006 | AB62: -1.1688164 | AC62: 1.0715797 | AD62: -0.016501272 | AE62: -1.4064491 | AF62: -0.15752638 | AG62: -2.038595 | AH62: 1.4312543 | AI62: -0.31882525 | AJ62: -0.38572984 | AK62: 0.32059502 | AL62: 0.40031772 | AM62: -1.9999105 | AN62: -1.3939438 | AO62: 0.3516656 | AP62: -1.5916389 | AQ62: 0.089305989 | AR62: 2.4834563 | AS62: 0.0006296959 | AT62: 0.35865762 | AU62: 0.25826128 | AV62: 1.3480748 | AW62: 0.27141216 | AX62: -0.81618362 | AY62: 0.33077988 | AZ62: 0.32347161 | BA62: -0.90187787 | BB62: -1.0451719 | BC62: 1.8917953 | BD62: -0.28921511 | BE62: -0.094369938 | BF62: -0.43543668 | BG62: 1.5921536 | BH62: -0.42053 | BI62: 1.6057866 | BJ62: 0.22393454 | BK62: -0.44880594 | BL62: -0.50296639 | BM62: 0.45276202 | BN62: 0.34616565 | BO62: 2.1381212 | BP62: -1.2300404 | BQ62: -0.58178824 | BR62: -0.54441535 | BS62: -0.47215521 | BT62: -0.2142818 | BU62: -0.50842339 | BV62: -1.6475628 | BW62: -0.60946484 | BX62: -3.2377357 | BY62: 0.43019656 | BZ62: -0.53745005 | CA62: -0.25607344 | CB62: 0.53662066 | CC62: -0.30848259 | CD62: -0.84927229 | CE62: 2.1248562 | CF62: -1.5090064 | CG62: -0.67012608 | CH62: 0.22208709 | CI62: 0.25083498 | CJ62: -0.3060921 | CK62: -1.0098238 | CL62: 1.4735299 | CM62: 0.26854869 | CN62: 0.63459729 | CO62: 0.16405472 | CP62: -0.33550848 | CQ62: 0.91895777 | CR62: 0.026375271 | CS62: -0.16591591 | CT62: 1.548544 | CU62: 0.49965162 | CV62: 0.1684067
A63: -2.4612794 | B63: -1.5197913 | C63: -0.9232051 | D63: 0.046528272 | E63: -1.7971789 | F63: -0.88425217 | G63: 0.048564968 | H63: 0.68364216 | I63: 1.276401 | J63: 0.11393298 | K63: -1.3684073 | L63: -0.3333304 | M63: -0.0027177427 | N63: -2.605137 | O63: -0.8114987 | P63: 1.2441256 | Q63: 2.6934714 | R63: -0.87692546 | S63: 1.4487416 | T63: -0.51282784 | U63: 0.35765476 | V63: 0.10040836 | W63: -0.20982712 | X63: 0.55133277 | Y63: -0.6116318 | Z63: 0.18137602 | AA63: -0.53971853 | AB63: -0.16059548 | AC63: -1.7242258 | AD63: 1.5464526 | AE63: 0.84153676 | AF63: 0.46981715 | AG63: -0.24397167 | AH63: -1.3709417 | AI63: 0.27615514 | AJ63: 1.080074 | AK63: 1.3470868 | AL63: 0.35617103 | AM63: 2.6108095 | AN63: 1.9073722 | AO63: -0.34889452 | AP63: 1.8920591 | AQ63: -0.8449728 | AR63: -0.96160739 | AS63: -0.1977551 | AT63: 0.37407495 | AU63: 1.961783 | AV63: -0.7724398 | AW63: 0.041004832 | AX63: -0.50868681 | AY63: -1.1818113 | AZ63: 0.7843156 | BA63: -0.092956538 | BB63: -0.52871725 | BC63: -2.1890646 | BD63: -0.40359123 | BE63: 1.4896729 | BF63: 1.4249842 | BG63: 0.87770063 | BH63: 0.1338212 | BI63: -1.7294733 | BJ63: 1.2184066 | BK63: -2.6748637 | BL63: -1.5393713 | BM63: 1.3250854 | BN63: 0.086045072 | BO63: -1.4149741 | BP63: 0.6622829 | BQ63: 0.5637236 | BR63: 0.36085204 | BS63: 0.97553836 | BT63: -0.22063659 | BU63: 0.60656085 | BV63: 1.2186695 | BW63: 0.71548715 | BX63: 0.99901988 | BY63: 1.2076183 | BZ63: 0.40554347 | CA63: -0.048722104 | CB63: -0.84080884 | CC63: 1.0723512 | CD63: 0.48040724 | CE63: 0.82215516 | CF63: -1.0202905 | CG63: 1.6991655 | CH63: 0.90521008 | CI63: 2.0506287 | CJ63: 0.26127303 | CK63: 0.18210548 | CL63: -2.0793195 | CM63: -0.51577072 | CN63: -0.36356009 | CO63: -0.14435069 | CP63: -0.36651702 | CQ63: -0.20062698 | CR63: -1.5597227 | CS63: -1.8182788 | CT63: 1.432203 | CU63: -0.12008105 | CV63: 0.13649134
A64: 0.99876329 | B64: -0.23621245 | C64: 0.74844991 | D64: 0.089935082 | E64: 0.21258452 | F64: 0.081449636 | G64: 0.55195386 | H64: 0.17765911 | I64: 0.21196183 | J64: 0.69023481 | K64: 0.95854446 | L64: 0.067075377 | M64: -0.91470927 | N64: 1.9758905 | O64: 0.067970504 | P64: -0.89947174 | Q64: -1.845991 | R64: 2.8355884 | S64: 0.30548861 | T64: 0.19688069 | U64: -0.40070718 | V64: 0.79351584 | W64: 1.5263557 | X64: 1.0194282 | Y64: -0.85418421 | Z64: 1.3391908 | AA64: 0.089023229 | AB64: 1.6839888 | AC64: 0.34020434 | AD64: 0.015744254 | AE64: -2.2566002 | AF64: 0.31371316 | AG64: 0.33105235 | AH64: 1.6102512 | AI64: -1.9863925 | AJ64: -0.19466218 | AK64: -3.5528852 | AL64: 0.073884642 | AM64: -0.33263281 | AN64: 0.0066323675 | AO64: 0.68866049 | AP64: -1.0825839 | AQ64: -1.192504 | AR64: 1.1434955 | AS64: -0.61156965 | AT64: -2.808362 | AU64: 0.94795869 | AV64: 1.1389063 | AW64: 2.0461186 | AX64: 1.5158802 | AY64: 1.2142172 | AZ64: 0.41701593 | BA64: -0.23588643 | BB64: 0.47913557 | BC64: -0.58024954 | BD64: -0.50478564 | BE64: -1.6544835 | BF64: 0.43036118 | BG64: -1.4252423 | BH64: -0.32741765 | BI64: -0.32987765 | BJ64: -0.31940855 | BK64: 2.4726023 | BL64: -1.0184477 | BM64: -0.96246334 | BN64: 1.2875002 | BO64: 1.7118444 | BP64: 1.0788255 | BQ64: 0.42951425 | BR64: 1.8933326 | BS64: -2.0360029 | BT64: 1.2351396 | BU64: -0.5809311 | BV64: -1.0947542 | BW64: -0.2629218 | BX64: -0.96101842 | BY64: -1.4501027 | BZ64: -1.4230169 | CA64: -0.63657501 | CB64: 0.32171335 | CC64: -1.0806061 | CD64: 0.29450672 | CE64: -1.2457635 | CF64: 0.60001103 | CG64: -0.0085481799 | CH64: 0.83985729 | CI64: -0.75264571 | CJ64: -0.87105129 | CK64: -0.19430297 | CL64: 0.42584426 | CM64: 1.403043 | CN64: -0.34302033 | CO64: 0.8381983 | CP64: 1.5510578 | CQ64: -1.4304633 | CR64: -0.31186904 | CS64: 1.3323572 | CT64: -1.5807874 | CU64: -1.1821892 | CV64: -0.16201845
A65: -1.2695076 | B65: -1.2220391 | C65: 0.19808519 | D65: -1.6478444 | E65: 0.1675735 | F65: -0.035489094 | G65: 0.50151621 | H65: 1.4955332 | I65: 0.077937508 | J65: 0.061521782 | K65: 0.51660376 | L65: 0.27637943 | M65: 0.070598624 | N65: -1.1090849 | O65: 0.54506601 | P65: -0.94440268 | Q65: -0.29182386 | R65: 0.22646985 | S65: -0.61013144 | T65: 0.79332936 | U65: -0.82048742 | V65: 0.21674513 | W65: -1.7089392 | X65: -1.0601728 | Y65: 0.54264896 | Z65: 0.22845751 | AA65: -0.68436762 | AB65: -1.0561522 | AC65: -0.63636674 | AD65: 0.67439043 | AE65: -0.86296206 | AF65: -0.96686813 | AG65: 0.90096686 | AH65: -0.03368527 | AI65: 1.1632938 | AJ65: 0.92400946 | AK65: 1.5610199 | AL65: -0.28374164 | AM65: -0.8871454 | AN65: 0.99451468 | AO65: 0.78162189 | AP65: 0.152108 | AQ65: -0.045322915 | AR65: -0.32071921 | AS65: 0.79418162 | AT65: 0.40936656 | AU65: 2.1829384 | AV65: -1.8848885 | AW65: -2.6108998 | AX65: -0.1775669 | AY65: -2.1399372 | AZ65: 1.1480412 | BA65: -0.70518188 | BB65: 1.4866434 | BC65: 1.3873807 | BD65: 0.3248563 | BE65: 1.7006899 | BF65: 0.11544242 | BG65: 1.0082498 | BH65: -0.0040986376 | BI65: 0.6462094 | BJ65: 0.22721219 | BK65: 0.2306341 | BL65: -0.032602602 | BM65: 1.127855 | BN65: -0.67302825 | BO65: -0.89308468 | BP65: 0.92127129 | BQ65: 0.67751981 | BR65: -0.46064741 | BS65: 0.30992516 | BT65: 0.2623437 | BU65: 1.3172474 | BV65: 1.1932784 | BW65: 1.1293903 | BX65: 1.5682503 | BY65: 0.50215651 | BZ65: 1.5975613 | CA65: 1.3785523 | CB65: 1.0953972 | CC65: 2.7030091 | CD65: -0.038164531 | CE65: 0.10347137 | CF65: 0.44591645 | CG65: -1.2159908 | CH65: -0.32786869 | CI65: 0.39365619 | CJ65: -0.33463405 | CK65: 1.6757575 | CL65: -0.035834416 | CM65: -0.035497712 | CN65: -0.61173305 | CO65: -0.33927276 | CP65: 1.1710582 | CQ65: -1.1768647 | CR65: 0.18099344 | CS65: 0.2359619 | CT65: 0.3114985 | CU65: -0.56401232 | CV65: 0.31993341
A66: -1.1559773 | B66: 0.051641086 | C66: 2.608251 | D66: -0.72985262 | E66: -0.29576541 | F66: 0.2132659 | G66: -0.48571784 | H66: -1.6369026 | I66: 1.1289014 | J66: -0.89246724 | K66: -1.1240904 | L66: 0.81188583 | M66: 0.33718364 | N66: 1.5361992 | O66: -0.68316797 | P66: -1.02171 | Q66: 0.42037762 | R66: 0.27288976 | S66: -0.9607998 | T66: 0.23619611 | U66: 1.4353981 | V66: -0.62654527 | W66: 1.1205909 | X66: 1.2460575 | Y66: -0.11153197 | Z66: -0.8157762 | AA66: -0.71581781 | AB66: -0.29944873 | AC66: -1.1991125 | AD66: -1.8672726 | AE66: 0.36671865 | AF66: 0.77531037 | AG66: -0.77322596 | AH66: 0.9310625 | AI66: -1.0295041 | AJ66: -0.49149801 | AK66: -2.3243642 | AL66: -1.8650732 | AM66: 0.092440868 | AN66: 0.38507375 | AO66: -0.52683582 | AP66: 0.064125481 | AQ66: -1.7330434 | AR66: 0.48318841 | AS66: 1.3078508 | AT66: 1.4653596 | AU66: -1.6613406 | AV66: -1.5154553 | AW66: 2.0791727 | AX66: -0.30011178 | AY66: 0.29468919 | AZ66: -0.63484493 | BA66: -0.82985593 | BB66: -1.0987399 | BC66: 0.7040187 | BD66: -0.43520417 | BE66: -2.0780123 | BF66: -0.60230868 | BG66: -0.062893972 | BH66: 0.097491373 | BI66: 1.9123655 | BJ66: 0.32427224 | BK66: 0.33702876 | BL66: -1.376938 | BM66: -0.48927696 | BN66: -0.80115648 | BO66: -0.98227465 | BP66: 1.644272 | BQ66: 0.17608069 | BR66: -0.7092728 | BS66: -1.2021864 | BT66: -4.0982893 | BU66: -0.11553181 | BV66: -1.4588376 | BW66: -1.7299796 | BX66: -0.74895332 | BY66: -0.45378172 | BZ66: -1.8594075 | CA66: -1.4370107 | CB66: -0.85861988 | CC66: -0.25283476 | CD66: 0.54830808 | CE66: -0.79024964 | CF66: 2.0400723 | CG66: 0.63908629 | CH66: 2.0757032 | CI66: 0.39640626 | CJ66: 1.499319 | CK66: -1.2368427 | CL66: -0.1640231 | CM66: 0.62744879 | CN66: 0.52860492 | CO66: -0.36045211 | CP66: -1.8091023 | CQ66: 1.4572288 | CR66: 0.18227395 | CS66: 1.4223672 | CT66: -0.82411962 | CU66: -0.30197324 | CV66: 0.70737109
A67: 0.21483594 | B67: 0.82877878 | C67: -1.5731715 | D67: -0.31689196 | E67: 0.40138457 | F67: 0.46113338 | G67: -0.62409434 | H67: -0.29699858 | I67: -0.0094892645 | J67: 0.050452744 | K67: 1.6171442 | L67: 0.28679675 | M67: 0.16552526 | N67: -0.72291043 | O67: 0.97878831 | P67: -1.1655104 | Q67: -1.0903372 | R67: -0.052281054 | S67: 0.46469975 | T67: 0.10707231 | U67: -2.1606036 | V67: 0.82632576 | W67: -0.49892617 | X67: -1.6591308 | Y67: 1.9209154 | Z67: -1.255479 | AA67: -0.50207083 | AB67: 2.1421539 | AC67: 0.30928654 | AD67: 1.3982046 | AE67: 0.69549698 | AF67: -1.5431828 | AG67: 0.79104107 | AH67: 0.69183454 | AI67: -0.40184212 | AJ67: -1.2791702 | AK67: 1.7425967 | AL67: 1.1398921 | AM67: 0.89146165 | AN67: 1.2879554 | AO67: 0.21494243 | AP67: -0.31651048 | AQ67: -0.9045467 | AR67: 0.43408662 | AS67: -0.11661941 | AT67: -1.5757079 | AU67: 1.0509644 | AV67: 1.7492366 | AW67: -0.019567093 | AX67: 0.99645332 | AY67: -0.58048252 | AZ67: 0.59888822 | BA67: -1.1946369 | BB67: -1.0346078 | BC67: 0.92288019 | BD67: 1.3728753 | BE67: 1.1595081 | BF67: -1.3327843 | BG67: 0.33785066 | BH67: -0.19070109 | BI67: 1.0639396 | BJ67: 0.76782382 | BK67: 2.3412744 | BL67: 1.672576 | BM67: -1.6633848 | BN67: 1.1648453 | BO67: -1.9167634 | BP67: 0.35441904 | BQ67: 0.87895532 | BR67: 1.1484105 | BS67: -0.056994432 | BT67: 0.88453697 | BU67: -0.032924676 | BV67: -0.62070937 | BW67: -1.2082288 | BX67: 1.1842502 | BY67: 1.7450651 | BZ67: 2.0756846 | CA67: -0.74212904 | CB67: -0.66936394 | CC67: -0.27948455 | CD67: 0.13060897 | CE67: -0.23354639 | CF67: -0.10238113 | CG67: -2.5267283 | CH67: -0.21730144 | CI67: 1.3042291 | CJ67: -2.4349935 | CK67: 1.9974612 | CL67: -0.95973851 | CM67: -1.9368212 | CN67: 1.2003745 | CO67: -1.0491234 | CP67: 0.17116681 | CQ67: -0.80044843 | CR67: 0.45250249 | CS67: 0.97543745 | CT67: 0.22540677 | CU67: 0.35860439 | CV67: -0.41749935
A68: -0.45059274 | B68: -0.049731192 | C68: 1.5707391 | D68: -0.68438291 | E68: 0.095908971 | F68: -0.28353942 | G68: 1.1728726 | H68: 0.84617935 | I68: 1.8216667 | J68: 0.56962841 | K68: -1.9520036 | L68: 1.8975821 | M68: -0.046750695 | N68: 0.07378374 | O68: 0.20629062 | P68: -0.56773173 | Q68: -0.57450462 | R68: 0.96647449 | S68: -1.3492972 | T68: 0.26860689 | U68: 0.86261602 | V68: 1.9864982 | W68: 1.4917618 | X68: -0.24291891 | Y68: -1.0547886 | Z68: -0.066217742 | AA68: 0.95635903 | AB68: -0.67168923 | AC68: 0.66188228 | AD68: 0.06581144 | AE68: -0.19804337 | AF68: -0.39065691 | AG68: 0.37564004 | AH68: -0.24332758 | AI68: -1.1737951 | AJ68: 0.2021501 | AK68: 0.91349457 | AL68: -0.62474682 | AM68: -0.30502793 | AN68: -0.55375527 | AO68: -0.88104359 | AP68: 0.14752698 | AQ68: 0.58971552 | AR68: 0.19091391 | AS68: 0.62232759 | AT68: 0.81464568 | AU68: -0.64671077 | AV68: 0.73121153 | AW68: -0.57564961 | AX68: -0.23183973 | AY68: -0.81963984 | AZ68: 0.74325448 | BA68: 0.68510257 | BB68: 1.2663278 | BC68: 0.53525128 | BD68: -0.84090524 | BE68: 0.43042455 | BF68: 1.2643665 | BG68: -0.60208693 | BH68: -0.25628068 | BI68: 1.3552365 | BJ68: 1.3128058 | BK68: -1.4093406 | BL68: -2.0218553 | BM68: 0.36341995 | BN68: -2.1067306 | BO68: 0.10514831 | BP68: 0.97286939 | BQ68: -2.3111561 | BR68: 0.91529141 | BS68: 1.3237149 | BT68: -0.60379952 | BU68: 0.74218387 | BV68: 1.3284874 | BW68: -1.2523972 | BX68: -1.1219976 | BY68: -0.33965464 | BZ68: -0.29447349 | CA68: 0.75453758 | CB68: 0.29271676 | CC68: 0.8408595 | CD68: -0.47501682 | CE68: 1.5831168 | CF68: 0.51924104 | CG68: -0.19610908 | CH68: 0.42605692 | CI68: -0.71159538 | CJ68: 0.83666272 | CK68: -1.6001648 | CL68: 0.77740974 | CM68: -0.21409852 | CN68: -1.0841628 | CO68: 1.2909636 | CP68: -0.48402581 | CQ68: 0.69293218 | CR68: -0.59874999 | CS68: -0.72714686 | CT68: -1.4493048 | CU68: -0.75683907 | CV68: 0.46500697
